> 异常处理是一种编程技术，用于检测、响应和恢复代码运行过程中的意外情况，确保程序在面对异常时能够保持稳定和可预测性。

![](https://photohosting.oss-cn-hangzhou.aliyuncs.com/notionCover/be784bec61724a3f83e6a04533161fd2.jpg)

## 1、异常的基本概念

### 1、C++异常处理机制

C++ 中的异常处理机制允许程序在运行时检测到错误并进行处理，以便程序可以优雅地恢复或者进行适当的清理操作。以下是 C++ 异常处理的基本概念和语法：

### 异常的基本语法

1. **抛出异常**：使用 `throw` 关键字抛出一个异常。可以抛出任何类型的数据，通常使用类对象来传递关于异常的信息。

   ```cpp
   throw SomeException("An error occurred");
   ```

2. **捕获异常**：使用 `try`、`catch` 和 `throw` 关键字来捕获异常。`try` 块中包含可能引发异常的代码，`catch` 块用于捕获和处理异常。

   ```cpp
   try {
       // 可能抛出异常的代码
       if (someCondition) {
           throw CustomException("Custom error");
       }
   }
   catch (const CustomException& e) {
       // 捕获并处理异常
       std::cerr << "Caught CustomException: " << e.what() << std::endl;
   }
   catch (const std::exception& e) {
       // 捕获标准库异常
       std::cerr << "Caught std::exception: " << e.what() << std::endl;
   }
   catch (...) {
       // 捕获任何其他异常
       std::cerr << "Caught unknown exception" << std::endl;
   }
   ```

### 异常处理的工作原理

- 当 `throw` 语句执行时，程序将控制权从当前执行点转移至最近的 `try` 块之外的匹配的 `catch` 块。
- 如果没有匹配的 `catch` 块，则程序将终止（默认情况下，未捕获的异常会导致 `std::terminate()` 被调用）。
- `catch` 块的参数通常是异常对象的引用，可以使用 `what()` 方法访问异常的描述信息。

### 异常的类型

- **标准异常**：C++ 标准库提供了许多异常类，例如 `std::exception` 及其派生类，如 `std::runtime_error`、`std::logic_error` 等，用于表示不同类型的运行时错误。
- **自定义异常**：可以通过继承标准异常类或直接实现 `std::exception` 接口来定义自己的异常类，以便于在程序中使用特定的异常类型和信息。

### 异常的最佳实践

- **精确捕获**：尽可能精确地捕获和处理异常，以便于针对不同类型的异常进行特定的处理。
- **异常安全性**：在设计函数和类时考虑异常安全性，确保在抛出异常时资源能够被正确管理和释放，避免内存泄漏和资源泄漏。
- **适度使用**：异常应该用于处理真正意外和无法预见的错误情况，而不是作为常规控制流的一部分。

通过合理使用异常处理机制，可以使 C++ 程序更加健壮和可靠，提高代码的可维护性和可读性。

### 2、标准异常类的层次结构

在 C++ 标准库中，异常类之间存在一定的层次结构，主要围绕着 `std::exception` 类展开。这个层次结构通常如下所示：

1. **std::exception**
   - `std::logic_error`
     - `std::invalid_argument`
     - `std::domain_error`
     - `std::length_error`
     - `std::out_of_range`
   - `std::runtime_error`
     - `std::range_error`
     - `std::overflow_error`
     - `std::underflow_error`
     - `std::system_error`
     - `std::ios_base::failure`

### 主要的标准异常类说明：

- **std::exception**：
  - 是所有标准异常类的基类。
  - 定义了一个 `what()` 成员函数，用于返回异常的描述信息。

- **std::logic_error**：
  - 表示由于程序逻辑错误引起的异常。
  - 常见的子类包括：
    - `std::invalid_argument`：传递给函数的参数无效。
    - `std::domain_error`：数学运算超出定义域。
    - `std::length_error`：容器长度超出支持范围。
    - `std::out_of_range`：访问超出有效范围的值。

- **std::runtime_error**：
  - 表示由于运行时条件引起的异常。
  - 常见的子类包括：
    - `std::range_error`：数值超出可表示的范围。
    - `std::overflow_error`：算术运算溢出。
    - `std::underflow_error`：算术运算下溢。
    - `std::system_error`：底层操作系统或库的错误。
    - `std::ios_base::failure`：输入/输出操作失败。

这些异常类提供了一种结构化的方式来处理不同类型的运行时错误，并且通过继承和多态性，可以方便地捕获和处理特定类型的异常。在实际编程中，选择合适的异常类可以提高程序的可读性和可维护性，同时确保程序在面对异常情况时能够有针对性地进行处理。

当使用标准异常类时，以下是一些常见的例子，展示了如何创建和处理这些异常：

### std::invalid_argument

```cpp
#include <stdexcept>
#include <iostream>

void processValue(int value) {
    if (value <= 0) {
        throw std::invalid_argument("Value must be positive");
    }
    // Process value here
}

int main() {
    try {
        processValue(-5);
    } catch (const std::invalid_argument& e) {
        std::cerr << "Invalid argument exception caught: " << e.what() << std::endl;
    }
    return 0;
}
```

### std::out_of_range

```cpp
#include <stdexcept>
#include <vector>
#include <iostream>

int main() {
    std::vector<int> vec = {1, 2, 3};
    try {
        int index = 5;
        if (index >= vec.size()) {
            throw std::out_of_range("Index out of range");
        }
        // Access vector element at index
        int value = vec.at(index);  // throws std::out_of_range if index is out of bounds
        std::cout << "Value at index " << index << ": " << value << std::endl;
    } catch (const std::out_of_range& e) {
        std::cerr << "Out of range exception caught: " << e.what() << std::endl;
    }
    return 0;
}
```

### std::runtime_error

```cpp
#include <stdexcept>
#include <iostream>

void doSomething() {
    // Simulate runtime error
    bool errorOccurred = true;
    if (errorOccurred) {
        throw std::runtime_error("Runtime error occurred");
    }
    // Process normally
}

int main() {
    try {
        doSomething();
    } catch (const std::runtime_error& e) {
        std::cerr << "Runtime error caught: " << e.what() << std::endl;
    }
    return 0;
}
```

### std::ios_base::failure

```cpp
#include <stdexcept>
#include <fstream>
#include <iostream>

void readFile(const std::string& filename) {
    std::ifstream file(filename);
    if (!file.is_open()) {
        throw std::ios_base::failure("Failed to open file");
    }
    // Read file contents
}

int main() {
    try {
        readFile("nonexistentfile.txt");
    } catch (const std::ios_base::failure& e) {
        std::cerr << "File I/O failure caught: " << e.what() << std::endl;
    }
    return 0;
}
```

这些例子展示了如何使用不同的标准异常类来捕获和处理特定类型的异常情况，从而增强程序的健壮性和可靠性。在实际应用中，可以根据具体的情况选择合适的异常类，以便于更精确地定位和处理异常。

## 2、try-catch块的使用
### 1、异常捕获和处理

在C++中，异常处理是一种用于处理程序运行时错误的重要机制。异常处理允许程序员在错误发生时，通过一组特定的语句捕获和处理异常，而不是简单地终止程序运行。以下是在C++中如何捕获和处理异常的基本方法：

### 1. 抛出异常

在程序中，可以使用 `throw` 关键字抛出异常。抛出异常时，可以抛出任何类型的对象，通常推荐使用标准异常类或自定义异常类。

```cpp
#include <stdexcept>

void processValue(int value) {
    if (value <= 0) {
        throw std::invalid_argument("Value must be positive");
    }
    // Process value here
}
```

### 2. 捕获异常

使用 `try` 和 `catch` 块来捕获异常。`try` 块包含可能引发异常的代码，而 `catch` 块用于捕获并处理异常。

```cpp
int main() {
    try {
        processValue(-5);  // This will throw std::invalid_argument
    } catch (const std::invalid_argument& e) {
        std::cerr << "Invalid argument exception caught: " << e.what() << std::endl;
    }
    return 0;
}
```

### 3. 多个 catch 块

可以使用多个 `catch` 块来捕获不同类型的异常，以便根据具体的异常类型执行不同的处理逻辑。

```cpp
int main() {
    try {
        processValue(-5);  // This will throw std::invalid_argument
    } catch (const std::invalid_argument& e) {
        std::cerr << "Invalid argument exception caught: " << e.what() << std::endl;
    } catch (const std::exception& e) {
        // Catch other standard exceptions
        std::cerr << "Standard exception caught: " << e.what() << std::endl;
    } catch (...) {
        // Catch all other exceptions
        std::cerr << "Unknown exception caught" << std::endl;
    }
    return 0;
}
```

### 4. 异常传播

在函数调用链中，如果未在当前函数中捕获异常，异常将传播到调用栈中的上一级函数，直到遇到能够处理该异常的 `catch` 块或者程序终止。

```cpp
void doSomething() {
    try {
        processValue(-5);  // This will throw std::invalid_argument
    } catch (const std::invalid_argument& e) {
        std::cerr << "Invalid argument exception caught: " << e.what() << std::endl;
        // Optionally rethrow the exception to propagate it further
        throw;
    }
}

int main() {
    try {
        doSomething();
    } catch (const std::exception& e) {
        std::cerr << "Exception caught in main: " << e.what() << std::endl;
    }
    return 0;
}
```

### 5. 自定义异常类

除了使用标准异常类外，还可以定义自己的异常类来提供更具体的异常信息和处理方法，从而增强程序的可读性和健壮性。

```cpp
#include <iostream>
#include <string>

class CustomException : public std::exception {
private:
    std::string msg;
public:
    CustomException(const std::string& message) : msg(message) {}
    const char* what() const noexcept override {
        return msg.c_str();
    }
};

void processValue(int value) {
    if (value <= 0) {
        throw CustomException("Value must be positive");
    }
    // Process value here
}

int main() {
    try {
        processValue(-5);  // This will throw CustomException
    } catch (const CustomException& e) {
        std::cerr << "Custom exception caught: " << e.what() << std::endl;
    }
    return 0;
}
```

在实际编程中，合理使用异常处理机制可以有效地提高程序的稳定性和可维护性，但也要注意避免过度使用异常来控制程序流程，以免引入不必要的复杂性。

### 2、多重catch块和异常再抛出

在C++中，多重 `catch` 块和异常再抛出（rethrowing exceptions）是异常处理中常见的技术，用于处理和传递异常信息。下面详细介绍这两个概念的用法：

### 多重 catch 块

多重 `catch` 块允许根据不同的异常类型执行特定的异常处理代码。在 `try` 块中，可以依次列出多个 `catch` 块来捕获不同类型的异常，并且它们按顺序处理异常，匹配第一个符合条件的 `catch` 块。

```cpp
#include <iostream>
#include <stdexcept>

void processValue(int value) {
    if (value == 0) {
        throw std::invalid_argument("Value cannot be zero");
    } else if (value < 0) {
        throw std::out_of_range("Value out of range");
    }
    // Process value here
}

int main() {
    try {
        processValue(-5);  // This will throw std::out_of_range
    } catch (const std::invalid_argument& e) {
        std::cerr << "Invalid argument exception caught: " << e.what() << std::endl;
    } catch (const std::out_of_range& e) {
        std::cerr << "Out of range exception caught: " << e.what() << std::endl;
    } catch (const std::exception& e) {
        // Catch all other standard exceptions
        std::cerr << "Standard exception caught: " << e.what() << std::endl;
    } catch (...) {
        // Catch all other exceptions
        std::cerr << "Unknown exception caught" << std::endl;
    }
    return 0;
}
```

在上面的示例中，`processValue(-5)` 抛出 `std::out_of_range` 异常，它会被第二个 `catch` 块捕获，并输出相应的错误信息。

### 异常再抛出

异常再抛出指的是在 `catch` 块中，通过 `throw;` 语句重新抛出当前捕获的异常，使得该异常能够传播到调用栈的上层。这种技术通常在 `catch` 块中进行，用于捕获并处理异常后，决定将异常传递给更高级的处理层次。

```cpp
#include <iostream>
#include <stdexcept>

void processValue(int value) {
    if (value == 0) {
        throw std::invalid_argument("Value cannot be zero");
    } else if (value < 0) {
        throw std::out_of_range("Value out of range");
    }
    // Process value here
}

void handleValue(int value) {
    try {
        processValue(value);
    } catch (const std::exception& e) {
        std::cerr << "Exception caught in handleValue: " << e.what() << std::endl;
        // Rethrow the exception to propagate it further
        throw;  // This rethrows the caught exception
    }
}

int main() {
    try {
        handleValue(-5);  // This will throw std::out_of_range
    } catch (const std::exception& e) {
        std::cerr << "Exception caught in main: " << e.what() << std::endl;
    }
    return 0;
}
```

在上面的示例中，`handleValue(-5)` 调用 `processValue(-5)` 导致 `std::out_of_range` 异常被捕获并处理，然后在 `handleValue` 函数中使用 `throw;` 重新抛出该异常。在 `main` 函数中捕获到了这个异常，并打印相应的错误信息。

### 注意事项

- **异常类型的顺序**：`catch` 块的顺序很重要，因为异常会被第一个匹配到的 `catch` 块处理，后续的 `catch` 块不会执行。
  
- **异常再抛出的语法**：使用 `throw;` 而不是 `throw e;` 来再抛出当前捕获的异常。这样做可以保持异常的类型和信息不变，使得异常处理更加清晰和有效。

异常处理在C++中是确保程序健壮性和稳定性的重要工具，有效的异常处理能够帮助开发者更好地管理和响应程序中的错误情况。

## 3、自定义异常类
### 1、派生自std::exception的自定义异常类

在C++中，派生自 `std::exception` 的自定义异常类可以通过继承 `std::exception` 类来实现。这种做法可以保持与标准库异常类的兼容性，并且可以利用标准异常类提供的一些基本功能，比如提供异常信息的 `what()` 方法。

下面是一个简单的示例，展示了如何定义一个派生自 `std::exception` 的自定义异常类：

```cpp
#include <iostream>
#include <exception>

// Custom exception class derived from std::exception
class MyException : public std::exception {
private:
    std::string errorMessage;  // Custom error message for the exception

public:
    // Constructor with error message
    MyException(const std::string& msg) : errorMessage(msg) {}

    // Override what() to provide exception description
    const char* what() const noexcept override {
        return errorMessage.c_str();
    }
};

// Example function that throws MyException
void processValue(int value) {
    if (value == 0) {
        throw MyException("Value cannot be zero");
    } else if (value < 0) {
        throw MyException("Value out of range");
    }
    // Process value here
}

int main() {
    try {
        processValue(0);  // This will throw MyException
    } catch (const MyException& e) {
        std::cerr << "MyException caught: " << e.what() << std::endl;
    } catch (const std::exception& e) {
        // Catch any standard library exceptions
        std::cerr << "Standard exception caught: " << e.what() << std::endl;
    } catch (...) {
        // Catch any other exceptions
        std::cerr << "Unknown exception caught" << std::endl;
    }
    return 0;
}
```

### 解析示例：

1. **自定义异常类 `MyException`**：
   - `MyException` 类继承自 `std::exception`，这使得它能够被其他代码和标准库正常处理。
   - 它有一个私有成员 `errorMessage`，用于存储异常的具体信息。

2. **构造函数**：
   - `MyException(const std::string& msg)` 构造函数接收一个 `std::string` 参数，用来初始化 `errorMessage`。

3. **重写 `what()` 方法**：
   - `what()` 方法是 `std::exception` 类的虚函数，被重写以返回异常描述信息的 C-style 字符串。

4. **异常抛出和捕获**：
   - `processValue(int value)` 函数根据条件抛出 `MyException` 异常。
   - `main()` 函数中的 `try-catch` 块捕获 `MyException` 类型的异常，并输出相应的错误信息。

通过这种方式，自定义异常类可以方便地与标准异常类集成，同时提供特定于应用程序或库的自定义错误信息和处理逻辑。

### 2、异常类的层次结构设计

在设计异常类的层次结构时，可以根据应用程序的需要和异常的分类来进行组织和设计。一个良好设计的异常类层次结构可以提高代码的可维护性和可读性，并且有助于更精确地捕获和处理不同类型的异常情况。

### 基本原则和设计考虑：

1. **继承自 `std::exception`**：
   - 所有自定义异常类应该继承自 `std::exception` 或其派生类，以保证与标准异常类的兼容性，并能够使用 `what()` 方法返回异常的描述信息。

2. **异常的分类**：
   - 根据异常的种类和应用场景，将异常进行逻辑上的分类。例如，可以根据不同的模块或功能区域定义不同的异常类。

3. **异常信息的提供**：
   - 每个异常类应该提供足够的信息来描述异常的原因和上下文，通常通过构造函数来初始化这些信息，并在 `what()` 方法中返回。

4. **异常类的继承关系**：
   - 使用继承来构建异常类的层次结构，从而可以更精确地捕获和处理特定类型的异常，同时可以在较高层次的 `catch` 块中捕获更通用的异常。

### 示例异常类的层次结构设计：

```cpp
#include <iostream>
#include <exception>

// Base exception class
class BaseException : public std::exception {
private:
    std::string errorMessage;

public:
    BaseException(const std::string& msg) : errorMessage(msg) {}

    const char* what() const noexcept override {
        return errorMessage.c_str();
    }
};

// Specific exception classes derived from BaseException
class NetworkException : public BaseException {
public:
    NetworkException(const std::string& msg) : BaseException(msg) {}
};

class DatabaseException : public BaseException {
public:
    DatabaseException(const std::string& msg) : BaseException(msg) {}
};

class FileIOException : public BaseException {
public:
    FileIOException(const std::string& msg) : BaseException(msg) {}
};

// Example function throwing exceptions
void simulateNetworkError() {
    throw NetworkException("Network connection lost");
}

void simulateDatabaseError() {
    throw DatabaseException("Database query failed");
}

void simulateFileError() {
    throw FileIOException("File not found");
}

int main() {
    try {
        simulateNetworkError();
        //simulateDatabaseError();
        //simulateFileError();
    } catch (const NetworkException& e) {
        std::cerr << "NetworkException caught: " << e.what() << std::endl;
    } catch (const DatabaseException& e) {
        std::cerr << "DatabaseException caught: " << e.what() << std::endl;
    } catch (const FileIOException& e) {
        std::cerr << "FileIOException caught: " << e.what() << std::endl;
    } catch (const BaseException& e) {
        std::cerr << "BaseException caught: " << e.what() << std::endl;
    } catch (const std::exception& e) {
        std::cerr << "Standard exception caught: " << e.what() << std::endl;
    } catch (...) {
        std::cerr << "Unknown exception caught" << std::endl;
    }

    return 0;
}
```

### 解析示例：

- **基本异常类 `BaseException`**：
  - 所有自定义异常类的基类，继承自 `std::exception`，提供了存储和返回异常信息的基本功能。

- **具体异常类**：
  - `NetworkException`、`DatabaseException` 和 `FileIOException` 分别表示网络、数据库和文件操作相关的异常。

- **异常抛出和捕获**：
  - `simulateNetworkError()`、`simulateDatabaseError()` 和 `simulateFileError()` 函数分别抛出不同类型的异常。
  - `main()` 函数中的 `try-catch` 块按照异常类的继承关系捕获异常，从具体到泛化，确保可以有效地处理各种异常情况。

这种设计方式使得异常处理更加精细和可控，能够根据实际需求对不同类型的异常进行特定的处理和记录。